<?xml version="1.0" encoding="utf-8"?>
<robot name="bicopter">

  <link name="base">
    
    <inertial>
      <origin xyz="0.0 0.0 0.0" rpy="0.0 0.0 0.0"/>
      <mass value="0.3"/>
      <inertia ixx ="0.001" ixy="0.0" ixz="0.0" iyy="0.001" iyz="0.0" izz="0.001"/>
    </inertial>

    <visual>
      <origin xyz="0.0 0.0 0.0" rpy="0.0 0.0 0.0"/>
      <geometry>
        <mesh filename="C:\Users\lucae\git\bicopter\urdf\bicopter_base.stl"/>
      </geometry>
    </visual>
  
  </link>

  <link name="propmount_left">

    <inertial>
      <origin xyz="0.0 0.125 0.120" rpy="0.0 0.0 0.0"/>
      <mass value="0.1"/>
      <inertia ixx ="0.0" ixy="0.0" ixz="0.0" iyy="0.0" iyz="0.0" izz="0.0"/>
    </inertial>

    <visual>
      <origin xyz="0.0 0.125 0.120" rpy="0.0 0.0 0.0"/>
      <geometry>
        <mesh filename="C:\Users\lucae\git\bicopter\urdf\bicopter_propmount.stl"/>
      </geometry>
    </visual>

  </link>

  <link name="propmount_right">

    <inertial>
      <origin xyz="0.0 -0.125 0.120" rpy="0.0 0.0 0.0"/>
      <mass value="0.1"/>
      <inertia ixx ="0.0" ixy="0.0" ixz="0.0" iyy="0.0" iyz="0.0" izz="0.0"/>
    </inertial>

    <visual>
      <origin xyz="0.0 0.125 0.120" rpy="0.0 0.0 0.0"/>
      <geometry>
        <mesh filename="C:\Users\lucae\git\bicopter\urdf\bicopter_propmount.stl"/>
      </geometry>
    </visual>

  </link>

  <joint name="servo_left" type="revolute">
    <origin xyz="0.0 0.125 0.120" rpy="0.0 0.0 0.0"/>
    <parent link="base"/>
    <child link="propmount_left"/>
    <axis xyz="0 1 0"/>
    <limit lower="-0.785" upper ="0.785"/>
  </joint>

  <joint name="servo_right" type="revolute">
    <origin xyz="0.0 -0.125 0.120" rpy="0.0 0.0 0.0"/>
    <parent link="base"/>
    <child link="propmount_left"/>
    <axis xyz="0 1 0"/>
    <limit lower="-0.785" upper ="0.785"/>
  </joint>
  
</robot>