<?xml version="1.0" encoding="utf-8"?>
<robot name="bicopter">

  <link name="base">
    
    <inertial>
      <origin xyz="0.0 0.0 0.0" rpy="0.0 0.0 0.0"/>
      <mass value="0.4"/>
      <inertia ixx ="0.003" ixy="0.0" ixz="0.0" iyy="0.001" iyz="0.0" izz="0.003"/>
    </inertial>

    <visual>
      <origin xyz="0.0 0.0 0.0" rpy="0.0 0.0 0.0"/>
      <geometry>
        <mesh filename="/home/ebnerl/catkin_ws/src/bicopter/bicopter_pybullet_controller/urdf/bicopter_base.stl" scale="0.001 0.001 0.001"/>
      </geometry>
    </visual>

    <collision>
      <origin xyz="0.0 0.0 0.0" rpy="0.0 0.0 0.0"/>
      <geometry>
        <mesh filename="/home/ebnerl/catkin_ws/src/bicopter/bicopter_pybullet_controller/urdf/bicopter_base.stl" scale="0.001 0.001 0.001"/>
      </geometry>
    </collision>
  </link>

  <link name="propmount_left">

    <inertial>
      <origin xyz="0.0 0.0 0.0" rpy="0.0 0.0 0.0"/>
      <mass value="0.1"/>
      <inertia ixx ="0.000005" ixy="0.0" ixz="0.0" iyy="0.0000005" iyz="0.0" izz="0.000005"/>
    </inertial>

    <visual>
      <origin xyz="0.0 0.0 0.0" rpy="0.0 0.0 0.0"/>
      <geometry>
        <mesh filename="/home/ebnerl/catkin_ws/src/bicopter/bicopter_pybullet_controller/urdf/bicopter_propmount.stl" scale="0.001 0.001 0.001"/>
      </geometry>
      <material name="Green">
        <color rgba="0.0 1.0 0.0 1.0"/>
      </material>
    </visual>

    <collision>
      <origin xyz="0.0 0.0 0.0" rpy="0.0 0.0 0.0"/>
      <geometry>
        <mesh filename="/home/ebnerl/catkin_ws/src/bicopter/bicopter_pybullet_controller/urdf/bicopter_propmount.stl" scale="0.001 0.001 0.001"/>
      </geometry>
    </collision>

  </link>

  <link name="propmount_right">

    <inertial>
      <origin xyz="0.0 0.0 0.0" rpy="0.0 0.0 0.0"/>
      <mass value="0.1"/>
      <inertia ixx ="0.000005" ixy="0.0" ixz="0.0" iyy="0.000005" iyz="0.0" izz="0.000005"/>
    </inertial>

    <visual>
      <origin xyz="0.0 0.0 0.0" rpy="0.0 0.0 0.0"/>
      <geometry>
        <mesh filename="/home/ebnerl/catkin_ws/src/bicopter/bicopter_pybullet_controller/urdf/bicopter_propmount.stl" scale="0.001 0.001 0.001"/>
      </geometry>
      <material name="Blue">
        <color rgba="0.0 0.0 1.0 1.0"/>
      </material>
    </visual>

    <collision>
      <origin xyz="0.0 0.0 0.0" rpy="0.0 0.0 0.0"/>
      <geometry>
        <mesh filename="/home/ebnerl/catkin_ws/src/bicopter/bicopter_pybullet_controller/urdf/bicopter_propmount.stl" scale="0.001 0.001 0.001"/>
      </geometry>
    </collision>

  </link>

  <joint name="servo_left" type="revolute">
    <origin xyz="0.0 0.110 0.120" rpy="0.0 0.0 0.0"/>
    <parent link="base"/>
    <child link="propmount_left"/>
    <axis xyz="0 1 0"/>
    <limit lower="-0.785" upper ="0.785"/>
  </joint>

  <joint name="servo_right" type="revolute">
    <origin xyz="0.0 -0.110 0.120" rpy="0.0 0.0 0.0"/>
    <parent link="base"/>
    <child link="propmount_right"/>
    <axis xyz="0 1 0"/>
    <limit lower="-0.785" upper ="0.785"/>
  </joint>
  
</robot>